# test-followページ「ユーザーが見つかりません」エラー原因分析レポート

## エラー概要
- **発生場所**: http://localhost:3000/test-follow
- **症状**: フォローボタンクリック時に「ユーザーが見つかりません」エラー表示
- **影響範囲**: test-followページの特定セクション（user6〜user11使用箇所）
- **報告日時**: 2025-08-26 16:30 JST

## 1. 問題の真の原因

### 1.1 直接的原因
test-followページで使用しているユーザーID（user6〜user11）がデータベースに存在しない。

### 1.2 根本原因
**ユーザーID定義とデータシード間の不整合**

#### test-followページの定義（11個のID）
```typescript
// src/app/test-follow/page.tsx (lines 31-43)
const TEST_USER_IDS = {
  user1: '507f1f77bcf86cd799439001',  // ✅ 存在
  user2: '507f1f77bcf86cd799439002',  // ✅ 存在
  user3: '507f1f77bcf86cd799439003',  // ✅ 存在
  user4: '507f1f77bcf86cd799439004',  // ✅ 存在
  user5: '507f1f77bcf86cd799439005',  // ✅ 存在
  user6: '507f1f77bcf86cd799439006',  // ❌ 存在しない
  user7: '507f1f77bcf86cd799439007',  // ❌ 存在しない
  user8: '507f1f77bcf86cd799439008',  // ❌ 存在しない
  user9: '507f1f77bcf86cd799439009',  // ❌ 存在しない
  user10: '507f1f77bcf86cd799439010', // ❌ 存在しない
  user11: '507f1f77bcf86cd799439011', // ❌ 存在しない
};
```

#### seed-test-users.jsの定義（5個のID + メインユーザー1個）
```javascript
// scripts/seed-test-users.js (lines 40-91)
const testUsers = [
  { _id: new mongoose.Types.ObjectId('507f1f77bcf86cd799439001'), ... }, // user1
  { _id: new mongoose.Types.ObjectId('507f1f77bcf86cd799439002'), ... }, // user2
  { _id: new mongoose.Types.ObjectId('507f1f77bcf86cd799439003'), ... }, // user3
  { _id: new mongoose.Types.ObjectId('507f1f77bcf86cd799439004'), ... }, // user4
  { _id: new mongoose.Types.ObjectId('507f1f77bcf86cd799439005'), ... }, // user5
  { _id: new mongoose.Types.ObjectId('507f1f77bcf86cd799439999'), ... }, // メインユーザー
  // user6〜user11は定義されていない
];
```

## 2. エラー発生フロー

### 2.1 エラー発生の流れ
```
1. ユーザーがtest-followページにアクセス
2. user6〜user11を使用するフォローボタンが表示される
3. ユーザーがボタンをクリック
4. FollowButtonコンポーネントがAPI呼び出し: /api/follow/507f1f77bcf86cd799439006
5. APIがUser.findById(userId)でユーザー検索
6. ユーザーが見つからず404エラー返却
7. FollowButtonが404を受けて「ユーザーが見つかりません」を表示
```

### 2.2 関連コード

#### APIエンドポイント（404返却箇所）
```typescript
// src/app/api/follow/[userId]/route.ts (lines 63-73)
const targetUser = await User.findById(userId);
if (!targetUser) {
  return NextResponse.json(
    { 
      success: false,
      error: 'Target user not found' 
    },
    { status: 404 }
  );
}
```

#### FollowButtonコンポーネント（エラー表示箇所）
```typescript
// src/components/FollowButton.tsx (lines 71-73)
} else if (response.status === 404) {
  setError('ユーザーが見つかりません');
}
```

## 3. 影響範囲の詳細

### 3.1 影響を受けるtest-followページのセクション

| セクション | 使用ID | 影響 |
|-----------|--------|------|
| デフォルト状態 | user1, user2 | ✅ 正常動作 |
| サイズバリエーション | user3, user4, user5 | ✅ 正常動作 |
| **コンパクトモード** | **user6, user7** | **❌ エラー発生** |
| **カスタムテキスト** | **user8, user9** | **❌ エラー発生** |
| **アイコンのみ表示** | **user10, user11** | **❌ エラー発生** |

### 3.2 ページコード位置
```typescript
// src/app/test-follow/page.tsx
- コンパクトモード: lines 194-209
- カスタムテキスト: lines 211-228 
- アイコンのみ表示: lines 230-247
```

## 4. 検証実行結果

### 4.1 データベース確認
```bash
# scripts/test-follow-api.js 実行結果
=== test-followページで使用されるユーザーIDの存在確認 ===
✅ user1 (507f1f77bcf86cd799439001): 存在
✅ user2 (507f1f77bcf86cd799439002): 存在
✅ user3 (507f1f77bcf86cd799439003): 存在
✅ user4 (507f1f77bcf86cd799439004): 存在
✅ user5 (507f1f77bcf86cd799439005): 存在
❌ user6 (507f1f77bcf86cd799439006): 存在しない
❌ user7 (507f1f77bcf86cd799439007): 存在しない
❌ user8 (507f1f77bcf86cd799439008): 存在しない
❌ user9 (507f1f77bcf86cd799439009): 存在しない
❌ user10 (507f1f77bcf86cd799439010): 存在しない
❌ user11 (507f1f77bcf86cd799439011): 存在しない
```

### 4.2 シードスクリプト実行結果
```bash
# node scripts/seed-test-users.js 実行結果
✅ 作成: テストユーザー1 (test1@example.com) - ID: 507f1f77bcf86cd799439001
✅ 作成: テストユーザー2 (test2@example.com) - ID: 507f1f77bcf86cd799439002
✅ 作成: テストユーザー3 (test3@example.com) - ID: 507f1f77bcf86cd799439003
✅ 作成: テストユーザー4 (test4@example.com) - ID: 507f1f77bcf86cd799439004
✅ 作成: テストユーザー5 (test5@example.com) - ID: 507f1f77bcf86cd799439005
✅ 作成: メインテストユーザー (testmain@example.com) - ID: 507f1f77bcf86cd799439999
```

## 5. 問題の分類と影響度

### 5.1 問題分類
- **種別**: データ不整合バグ
- **カテゴリ**: テストデータ設定エラー
- **重要度**: 中（テスト環境のみ影響）
- **緊急度**: 低（本番環境に影響なし）

### 5.2 影響評価
- **開発効率への影響**: フォロー機能の完全なテストが不可能
- **デモへの影響**: test-followページでの機能デモが一部失敗
- **本番環境への影響**: なし（テストページ限定）

## 6. 解決策の提案（改善は実施せず）

### 6.1 短期的解決策
1. **Option A**: seed-test-users.jsにuser6〜user11を追加
2. **Option B**: test-followページからuser6〜user11の使用を削除
3. **Option C**: test-followページで動的にユーザーIDを取得

### 6.2 長期的改善案
1. テストデータ定義の一元管理
2. テストユーザーIDの自動生成機構
3. CI/CDでのテストデータ整合性チェック

## 7. 証拠とトレーサビリティ

### 7.1 関連ファイル
- `/src/app/test-follow/page.tsx` - テストページ実装
- `/src/components/FollowButton.tsx` - フォローボタンコンポーネント
- `/src/app/api/follow/[userId]/route.ts` - フォローAPI
- `/scripts/seed-test-users.js` - テストデータ作成スクリプト
- `/scripts/test-follow-api.js` - 検証スクリプト（本調査で作成）

### 7.2 実行ログ
- seed-test-users.js実行ログ: 2025-08-26 16:20 JST
- test-follow-api.js実行ログ: 2025-08-26 16:25 JST
- データベースユーザー総数: 19

### 7.3 検証コマンド
```bash
# テストユーザー作成
node scripts/seed-test-users.js

# ユーザー存在確認
node scripts/test-follow-api.js

# API直接テスト
curl -X POST http://localhost:3000/api/follow/507f1f77bcf86cd799439006
```

## 8. 結論

**問題の真の原因**：
test-followページが11個のテストユーザーIDを使用しているが、seed-test-users.jsスクリプトは5個のテストユーザー（+メインユーザー1個）しか作成していない。この不整合により、user6〜user11のフォローボタンをクリックした際、APIが404エラーを返し、「ユーザーが見つかりません」エラーが表示される。

**証拠署名**：
I attest: all numbers come from the attached evidence.
Evidence Hash: scripts/test-follow-api.js実行結果 + seed-test-users.js実行ログ + ソースコード行番号参照
作成完了: 2025-08-26 16:35 JST